Workbook

Sheet Summary
A1: BOQ Summary & Capital Structure (ETB)
A2: Elemental construction summary, then the full capex and funding structure. Ties exactly to the financial model.
A3: Element | B3: Amount ETB | C3: % of capex | D3: Note
A4: A Preliminaries & General | B4: ='Detailed BOQ'!F12 -> 377096310 | C4: =B4/$B$25 -> 0.072465573 | D4: 7 items
A5: B Substructure | B5: ='Detailed BOQ'!F25 -> 616199550 | C5: =B5/$B$25 -> 0.11841339 | D5: 11 items
A6: C Superstructure - Frame, Floors & Roof | B6: ='Detailed BOQ'!F34 -> 637545000 | C6: =B6/$B$25 -> 0.12251529 | D6: 7 items
A7: D External Envelope | B7: ='Detailed BOQ'!F40 -> 421106280 | C7: =B7/$B$25 -> 0.08092285 | D7: 4 items
A8: E Internal Divisions | B8: ='Detailed BOQ'!F46 -> 146718000 | C8: =B8/$B$25 -> 0.028194399 | D8: 4 items
A9: F Finishes | B9: ='Detailed BOQ'!F54 -> 339989680 | C9: =B9/$B$25 -> 0.065334893 | D9: 6 items
A10: G Fittings & Sanitary | B10: ='Detailed BOQ'!F58 -> 99915770 | C10: =B10/$B$25 -> 0.019200542 | D10: 2 items
A11: H Services / Mep | B11: ='Detailed BOQ'!F70 -> 799684370 | C11: =B11/$B$25 -> 0.15367317 | D11: 10 items
A12: I Specialist Systems | B12: ='Detailed BOQ'!F77 -> 543934690 | C12: =B12/$B$25 -> 0.10452645 | D12: 5 items
A13: J External Works (2,000 M2 Surface) | B13: ='Detailed BOQ'!F86 -> 81910350 | C13: =B13/$B$25 -> 0.015740489 | D13: 7 items
A14: TOTAL CONSTRUCTION WORKS (BOQ A-J) | B14: ='Detailed BOQ'!F87 -> 4064100000 | C14: =B14/$B$25 -> 0.78098705 | D14: Sum of the 10 BOQ elements
A16: DEVELOPMENT COST / CAPEX
A17: Construction works (BOQ A-J) | B17: =B14 -> 4064100000 | C17: =B17/$B$25 -> 0.78098705 | D17: Sum of the 10 BOQ elements
A18: In-house design @2% | B18: =0.02*B17 -> 81282000 | C18: =B18/$B$25 -> 0.015619741 | D18: TDOMA staff cost, capitalised per IAS 16.17(a); general overhead excluded per IAS 16.19(d)
A19: Specialist consultancy | B19: 16849500 | C19: =B19/$B$25 -> 0.0032379226 | D19: Industry norm, not a vendor quotation - specialist systems need external design
A20: Contingency @12% | B20: =0.12*(B17+B18+B19) -> 499467780 | C20: =B20/$B$25 -> 0.095981366 | D20: On construction + design + specialist
A21: Capital works | B21: =B17+B18+B19+B20 -> 4661699280 | C21: =B21/$B$25 -> 0.89582608
A22: FF&E - TDOMA scope | B22: 163020000 | C22: =B22/$B$25 -> 0.03132711 | D22: Common areas + HQ + hire-out venues. Operator fits out hotel; tenants fit out demises.
A23: IDC (IAS 23, capitalised) | B23: 360537467 | C23: =B23/$B$25 -> 0.069283505 | D23: Solved monthly on the IDC sheet - model is fully acyclic, no iteration needed
A24: Arrangement fee @1.5% | B24: 18542697 | C24: =B24/$B$25 -> 0.0035632997 | D24: Borrowing cost - IAS 23
A25: Building sub-total (CASH) | B25: =B21+B22+B23+B24 -> 5203799444 | C25: =B25/$B$25 -> 1
A26: Land (in-kind, NON-CASH) | B26: 1650000000 | C26: =B26/$B$25 -> 0.31707602 | D26: City's PPP contribution
A27: TOTAL CAPEX / DEVELOPMENT COST | B27: =B25+B26 -> 6853799444 | C27: =100% -> 1
A28: Pre-opening & marketing | B28: 120000000
A29: TOTAL USES | B29: =B27+B28 -> 6973799444
A31: FUNDING
A32: Cash requirement (ex-land) | B32: =B29-B26 -> 5323799444
A33: TDOMA equity (75% of cash) | B33: =0.75*B32 -> 3992849583
A34: City land (in-kind, non-cash) | B34: =B26 -> 1650000000
A35: Debt (25% of cash) | B35: =0.25*B32 -> 1330949861
A36: TOTAL SOURCES | B36: =B33+B26+B35 -> 6973799444
A37: CHECK: Sources - Uses | B37: =B36-B29 -> 0 | D37: Must be zero
A39: Input VAT recoverable on capex (refunded in year 1) | B39: 629311210
A40: Memo - USD @160 | B40: =B27/160 -> 42836247 | D40: Reference
A41: Capex per gross m2 | B41: 181317 | D41: Total capex / gross building area
A42: EFFECTIVE capex per TDOMA gross m2 (70%) | B42: 259025 | D42: TDOMA's 70% economic share of the building
A44: Note: elemental estimate at concept stage; re-measure from detailed drawings before tender. Rates in ETB, current mid-2026; verify with a quantity surveyor and current supplier quotations. Land is the City's non-cash PPP contribution; capitalised costs follow IAS 16/IAS 23 as noted.

Sheet Detailed BOQ
A1: Detailed Bill of Quantities (elemental / preliminary) - ETB
A2: Concept-stage elemental BOQ. Blue = input (Qty, Rate). Amount = Qty x Rate. Re-measure from detailed drawings before tender.
A3: Item | B3: Description | C3: Unit | D3: Qty | E3: Rate ETB | F3: Amount ETB
A4: A | B4: PRELIMINARIES & GENERAL
A5: A.1 | B5: Site establishment, hoarding, offices & welfare | C5: sum | D5: 1 | E5: 40021990 | F5: =D5*E5 -> 40021990
A6: A.2 | B6: Site management, supervision & staff | C6: month | D6: 36 | E6: 4002200 | F6: =D6*E6 -> 144079200
A7: A.3 | B7: Insurances, performance bond & permits | C7: sum | D7: 1 | E7: 48915770 | F7: =D7*E7 -> 48915770
A8: A.4 | B8: Temporary services (power, water, telecoms) | C8: sum | D8: 1 | E8: 26681330 | F8: =D8*E8 -> 26681330
A9: A.5 | B9: Health, safety & environmental management | C9: sum | D9: 1 | E9: 31128220 | F9: =D9*E9 -> 31128220
A10: A.6 | B10: Tower crane, hoists & major plant | C10: month | D10: 36 | E10: 1778760 | F10: =D10*E10 -> 64035360
A11: A.7 | B11: Testing, commissioning & handover | C11: sum | D11: 1 | E11: 22234440 | F11: =D11*E11 -> 22234440
B12: Subtotal A | F12: =SUM(F5:F11) -> 377096310
A13: B | B13: SUBSTRUCTURE
A14: B.1 | B14: Site clearance & strip | C14: m2 | D14: 5000 | E14: 360 | F14: =D14*E14 -> 1800000
A15: B.2 | B15: Bulk excavation for 3 basement levels | C15: m3 | D15: 42000 | E15: 1070 | F15: =D15*E15 -> 44940000
A16: B.3 | B16: Secant/contiguous pile retaining wall | C16: m2 | D16: 3600 | E16: 24900 | F16: =D16*E16 -> 89640000
A17: B.4 | B17: Dewatering during construction | C17: sum | D17: 1 | E17: 35575110 | F17: =D17*E17 -> 35575110
A18: B.5 | B18: Cart away & disposal of surplus | C18: m3 | D18: 42000 | E18: 620 | F18: =D18*E18 -> 26040000
A19: B.6 | B19: Blinding / lean concrete | C19: m2 | D19: 3000 | E19: 2220 | F19: =D19*E19 -> 6660000
A20: B.7 | B20: RC raft foundation | C20: m3 | D20: 3600 | E20: 28460 | F20: =D20*E20 -> 102456000
A21: B.8 | B21: RC basement retaining walls | C21: m3 | D21: 2400 | E21: 30240 | F21: =D21*E21 -> 72576000
A22: B.9 | B22: RC basement columns, beams & slabs (3 levels) | C22: m2 | D22: 9000 | E22: 19570 | F22: =D22*E22 -> 176130000
A23: B.10 | B23: Tanking / waterproofing to basement | C23: m2 | D23: 6600 | E23: 5780 | F23: =D23*E23 -> 38148000
A24: B.11 | B24: Basement drainage, sumps & pumps | C24: sum | D24: 1 | E24: 22234440 | F24: =D24*E24 -> 22234440
B25: Subtotal B | F25: =SUM(F14:F24) -> 616199550
A26: C | B26: SUPERSTRUCTURE - FRAME, FLOORS & ROOF
A27: C.1 | B27: RC columns (above grade) | C27: m3 | D27: 3200 | E27: 26680 | F27: =D27*E27 -> 85376000
A28: C.2 | B28: RC beams | C28: m3 | D28: 4000 | E28: 25790 | F28: =D28*E28 -> 103160000
A29: C.3 | B29: Transfer structure at podium/tower interface | C29: m3 | D29: 900 | E29: 40020 | F29: =D29*E29 -> 36018000
A30: C.4 | B30: Suspended RC floor slabs (above grade) | C30: m2 | D30: 28800 | E30: 12450 | F30: =D30*E30 -> 358560000
A31: C.5 | B31: RC roof slab & parapets | C31: m2 | D31: 1200 | E31: 13340 | F31: =D31*E31 -> 16008000
A32: C.6 | B32: RC staircases (all cores) | C32: m2 | D32: 1600 | E32: 16010 | F32: =D32*E32 -> 25616000
A33: C.7 | B33: Vehicle ramps | C33: m2 | D33: 900 | E33: 14230 | F33: =D33*E33 -> 12807000
B34: Subtotal C | F34: =SUM(F27:F33) -> 637545000
A35: D | B35: EXTERNAL ENVELOPE
A36: D.1 | B36: Unitised curtain walling / structural glazing | C36: m2 | D36: 8500 | E36: 28460 | F36: =D36*E36 -> 241910000
A37: D.2 | B37: Kinetic bronze facade shading system | C37: m2 | D37: 3500 | E37: 40020 | F37: =D37*E37 -> 140070000
A38: D.3 | B38: Solid cladding / rendered external walls | C38: m2 | D38: 2500 | E38: 10670 | F38: =D38*E38 -> 26675000
A39: D.4 | B39: Main entrance portals & revolving doors | C39: no | D39: 4 | E39: 3112820 | F39: =D39*E39 -> 12451280
B40: Subtotal D | F40: =SUM(F36:F39) -> 421106280
...
